2020-07-25 12:20:07,744 ERROR: Exception on / [GET] [in /home/jesse/PycharmProjects/Flask_template_site/venv/lib/python3.8/site-packages/flask/app.py:1891]
Traceback (most recent call last):
  File "/home/jesse/PycharmProjects/Flask_template_site/venv/lib/python3.8/site-packages/sqlalchemy/orm/relationships.py", line 2635, in _determine_joins
    self.primaryjoin = join_condition(
  File "<string>", line 2, in join_condition
  File "<string>", line 2, in _join_condition
  File "/home/jesse/PycharmProjects/Flask_template_site/venv/lib/python3.8/site-packages/sqlalchemy/util/deprecations.py", line 139, in warned
    return fn(*args, **kwargs)
  File "/home/jesse/PycharmProjects/Flask_template_site/venv/lib/python3.8/site-packages/sqlalchemy/sql/selectable.py", line 978, in _join_condition
    raise exc.NoForeignKeysError(
sqlalchemy.exc.NoForeignKeysError: Can't find any foreign key relationships between 'project' and 'user'.

The above exception was the direct cause of the following exception:

Traceback (most recent call last):
  File "/home/jesse/PycharmProjects/Flask_template_site/venv/lib/python3.8/site-packages/flask/app.py", line 2447, in wsgi_app
    response = self.full_dispatch_request()
  File "/home/jesse/PycharmProjects/Flask_template_site/venv/lib/python3.8/site-packages/flask/app.py", line 1952, in full_dispatch_request
    rv = self.handle_user_exception(e)
  File "/home/jesse/PycharmProjects/Flask_template_site/venv/lib/python3.8/site-packages/flask/app.py", line 1821, in handle_user_exception
    reraise(exc_type, exc_value, tb)
  File "/home/jesse/PycharmProjects/Flask_template_site/venv/lib/python3.8/site-packages/flask/_compat.py", line 39, in reraise
    raise value
  File "/home/jesse/PycharmProjects/Flask_template_site/venv/lib/python3.8/site-packages/flask/app.py", line 1950, in full_dispatch_request
    rv = self.dispatch_request()
  File "/home/jesse/PycharmProjects/Flask_template_site/venv/lib/python3.8/site-packages/flask/app.py", line 1936, in dispatch_request
    return self.view_functions[rule.endpoint](**req.view_args)
  File "/home/jesse/PycharmProjects/Flask_template_site/venv/lib/python3.8/site-packages/flask_login/utils.py", line 270, in decorated_view
    elif not current_user.is_authenticated:
  File "/home/jesse/PycharmProjects/Flask_template_site/venv/lib/python3.8/site-packages/werkzeug/local.py", line 347, in __getattr__
    return getattr(self._get_current_object(), name)
  File "/home/jesse/PycharmProjects/Flask_template_site/venv/lib/python3.8/site-packages/werkzeug/local.py", line 306, in _get_current_object
    return self.__local()
  File "/home/jesse/PycharmProjects/Flask_template_site/venv/lib/python3.8/site-packages/flask_login/utils.py", line 26, in <lambda>
    current_user = LocalProxy(lambda: _get_user())
  File "/home/jesse/PycharmProjects/Flask_template_site/venv/lib/python3.8/site-packages/flask_login/utils.py", line 346, in _get_user
    current_app.login_manager._load_user()
  File "/home/jesse/PycharmProjects/Flask_template_site/venv/lib/python3.8/site-packages/flask_login/login_manager.py", line 318, in _load_user
    user = self._user_callback(user_id)
  File "/home/jesse/PycharmProjects/Flask_template_site/app/models.py", line 13, in load_user
    return User.query.get(int(id))
  File "/home/jesse/PycharmProjects/Flask_template_site/venv/lib/python3.8/site-packages/flask_sqlalchemy/__init__.py", line 512, in __get__
    mapper = orm.class_mapper(type)
  File "/home/jesse/PycharmProjects/Flask_template_site/venv/lib/python3.8/site-packages/sqlalchemy/orm/base.py", line 451, in class_mapper
    mapper = _inspect_mapped_class(class_, configure=configure)
  File "/home/jesse/PycharmProjects/Flask_template_site/venv/lib/python3.8/site-packages/sqlalchemy/orm/base.py", line 430, in _inspect_mapped_class
    mapper._configure_all()
  File "/home/jesse/PycharmProjects/Flask_template_site/venv/lib/python3.8/site-packages/sqlalchemy/orm/mapper.py", line 1354, in _configure_all
    configure_mappers()
  File "/home/jesse/PycharmProjects/Flask_template_site/venv/lib/python3.8/site-packages/sqlalchemy/orm/mapper.py", line 3280, in configure_mappers
    mapper._post_configure_properties()
  File "/home/jesse/PycharmProjects/Flask_template_site/venv/lib/python3.8/site-packages/sqlalchemy/orm/mapper.py", line 1967, in _post_configure_properties
    prop.init()
  File "/home/jesse/PycharmProjects/Flask_template_site/venv/lib/python3.8/site-packages/sqlalchemy/orm/interfaces.py", line 197, in init
    self.do_init()
  File "/home/jesse/PycharmProjects/Flask_template_site/venv/lib/python3.8/site-packages/sqlalchemy/orm/relationships.py", line 2077, in do_init
    self._setup_join_conditions()
  File "/home/jesse/PycharmProjects/Flask_template_site/venv/lib/python3.8/site-packages/sqlalchemy/orm/relationships.py", line 2141, in _setup_join_conditions
    self._join_condition = jc = JoinCondition(
  File "/home/jesse/PycharmProjects/Flask_template_site/venv/lib/python3.8/site-packages/sqlalchemy/orm/relationships.py", line 2524, in __init__
    self._determine_joins()
  File "/home/jesse/PycharmProjects/Flask_template_site/venv/lib/python3.8/site-packages/sqlalchemy/orm/relationships.py", line 2657, in _determine_joins
    util.raise_(
  File "/home/jesse/PycharmProjects/Flask_template_site/venv/lib/python3.8/site-packages/sqlalchemy/util/compat.py", line 178, in raise_
    raise exception
sqlalchemy.exc.NoForeignKeysError: Could not determine join condition between parent/child tables on relationship Project.creator - there are no foreign keys linking these tables.  Ensure that referencing columns are associated with a ForeignKey or ForeignKeyConstraint, or specify a 'primaryjoin' expression.
2020-07-25 12:25:07,375 INFO: Flask-Template-Site startup [in /home/jesse/PycharmProjects/Flask_template_site/app/__init__.py:60]
2020-07-25 12:25:15,778 INFO: Flask-Template-Site startup [in /home/jesse/PycharmProjects/Flask_template_site/app/__init__.py:60]
2020-07-25 12:25:21,550 INFO: Flask-Template-Site startup [in /home/jesse/PycharmProjects/Flask_template_site/app/__init__.py:60]
2020-07-25 12:25:33,546 INFO: Flask-Template-Site startup [in /home/jesse/PycharmProjects/Flask_template_site/app/__init__.py:60]
2020-07-25 12:27:56,432 INFO: Flask-Template-Site startup [in /home/jesse/PycharmProjects/Flask_template_site/app/__init__.py:60]
2020-07-25 12:28:00,605 INFO: Flask-Template-Site startup [in /home/jesse/PycharmProjects/Flask_template_site/app/__init__.py:60]
2020-07-25 12:28:03,660 INFO: Flask-Template-Site startup [in /home/jesse/PycharmProjects/Flask_template_site/app/__init__.py:60]
2020-07-25 12:28:20,422 INFO: Flask-Template-Site startup [in /home/jesse/PycharmProjects/Flask_template_site/app/__init__.py:60]
2020-07-25 12:28:23,337 INFO: Flask-Template-Site startup [in /home/jesse/PycharmProjects/Flask_template_site/app/__init__.py:60]
2020-07-25 12:28:26,044 INFO: Flask-Template-Site startup [in /home/jesse/PycharmProjects/Flask_template_site/app/__init__.py:60]
2020-07-25 12:29:07,295 ERROR: Exception on /new_project [POST] [in /home/jesse/PycharmProjects/Flask_template_site/venv/lib/python3.8/site-packages/flask/app.py:1891]
Traceback (most recent call last):
  File "/home/jesse/PycharmProjects/Flask_template_site/venv/lib/python3.8/site-packages/sqlalchemy/engine/base.py", line 1277, in _execute_context
    self.dialect.do_execute(
  File "/home/jesse/PycharmProjects/Flask_template_site/venv/lib/python3.8/site-packages/sqlalchemy/engine/default.py", line 593, in do_execute
    cursor.execute(statement, parameters)
sqlite3.OperationalError: no such column: project.creator_id

The above exception was the direct cause of the following exception:

Traceback (most recent call last):
  File "/home/jesse/PycharmProjects/Flask_template_site/venv/lib/python3.8/site-packages/flask/app.py", line 2447, in wsgi_app
    response = self.full_dispatch_request()
  File "/home/jesse/PycharmProjects/Flask_template_site/venv/lib/python3.8/site-packages/flask/app.py", line 1952, in full_dispatch_request
    rv = self.handle_user_exception(e)
  File "/home/jesse/PycharmProjects/Flask_template_site/venv/lib/python3.8/site-packages/flask/app.py", line 1821, in handle_user_exception
    reraise(exc_type, exc_value, tb)
  File "/home/jesse/PycharmProjects/Flask_template_site/venv/lib/python3.8/site-packages/flask/_compat.py", line 39, in reraise
    raise value
  File "/home/jesse/PycharmProjects/Flask_template_site/venv/lib/python3.8/site-packages/flask/app.py", line 1950, in full_dispatch_request
    rv = self.dispatch_request()
  File "/home/jesse/PycharmProjects/Flask_template_site/venv/lib/python3.8/site-packages/flask/app.py", line 1936, in dispatch_request
    return self.view_functions[rule.endpoint](**req.view_args)
  File "/home/jesse/PycharmProjects/Flask_template_site/venv/lib/python3.8/site-packages/flask_login/utils.py", line 272, in decorated_view
    return func(*args, **kwargs)
  File "/home/jesse/PycharmProjects/Flask_template_site/app/routes.py", line 110, in new_project
    if form.validate_on_submit():
  File "/home/jesse/PycharmProjects/Flask_template_site/venv/lib/python3.8/site-packages/flask_wtf/form.py", line 100, in validate_on_submit
    return self.is_submitted() and self.validate()
  File "/home/jesse/PycharmProjects/Flask_template_site/venv/lib/python3.8/site-packages/wtforms/form.py", line 318, in validate
    return super(Form, self).validate(extra)
  File "/home/jesse/PycharmProjects/Flask_template_site/venv/lib/python3.8/site-packages/wtforms/form.py", line 150, in validate
    if not field.validate(self, extra):
  File "/home/jesse/PycharmProjects/Flask_template_site/venv/lib/python3.8/site-packages/wtforms/fields/core.py", line 226, in validate
    stop_validation = self._run_validation_chain(form, chain)
  File "/home/jesse/PycharmProjects/Flask_template_site/venv/lib/python3.8/site-packages/wtforms/fields/core.py", line 246, in _run_validation_chain
    validator(form, self)
  File "/home/jesse/PycharmProjects/Flask_template_site/app/forms.py", line 62, in validate_project_title
    title_check = Project.query.filter_by(title=project_title.data).first()
  File "/home/jesse/PycharmProjects/Flask_template_site/venv/lib/python3.8/site-packages/sqlalchemy/orm/query.py", line 3397, in first
    ret = list(self[0:1])
  File "/home/jesse/PycharmProjects/Flask_template_site/venv/lib/python3.8/site-packages/sqlalchemy/orm/query.py", line 3171, in __getitem__
    return list(res)
  File "/home/jesse/PycharmProjects/Flask_template_site/venv/lib/python3.8/site-packages/sqlalchemy/orm/query.py", line 3503, in __iter__
    return self._execute_and_instances(context)
  File "/home/jesse/PycharmProjects/Flask_template_site/venv/lib/python3.8/site-packages/sqlalchemy/orm/query.py", line 3528, in _execute_and_instances
    result = conn.execute(querycontext.statement, self._params)
  File "/home/jesse/PycharmProjects/Flask_template_site/venv/lib/python3.8/site-packages/sqlalchemy/engine/base.py", line 1014, in execute
    return meth(self, multiparams, params)
  File "/home/jesse/PycharmProjects/Flask_template_site/venv/lib/python3.8/site-packages/sqlalchemy/sql/elements.py", line 298, in _execute_on_connection
    return connection._execute_clauseelement(self, multiparams, params)
  File "/home/jesse/PycharmProjects/Flask_template_site/venv/lib/python3.8/site-packages/sqlalchemy/engine/base.py", line 1127, in _execute_clauseelement
    ret = self._execute_context(
  File "/home/jesse/PycharmProjects/Flask_template_site/venv/lib/python3.8/site-packages/sqlalchemy/engine/base.py", line 1317, in _execute_context
    self._handle_dbapi_exception(
  File "/home/jesse/PycharmProjects/Flask_template_site/venv/lib/python3.8/site-packages/sqlalchemy/engine/base.py", line 1511, in _handle_dbapi_exception
    util.raise_(
  File "/home/jesse/PycharmProjects/Flask_template_site/venv/lib/python3.8/site-packages/sqlalchemy/util/compat.py", line 178, in raise_
    raise exception
  File "/home/jesse/PycharmProjects/Flask_template_site/venv/lib/python3.8/site-packages/sqlalchemy/engine/base.py", line 1277, in _execute_context
    self.dialect.do_execute(
  File "/home/jesse/PycharmProjects/Flask_template_site/venv/lib/python3.8/site-packages/sqlalchemy/engine/default.py", line 593, in do_execute
    cursor.execute(statement, parameters)
sqlalchemy.exc.OperationalError: (sqlite3.OperationalError) no such column: project.creator_id
[SQL: SELECT project.id AS project_id, project.title AS project_title, project.description AS project_description, project.project_files_path AS project_project_files_path, project.creator_id AS project_creator_id 
FROM project 
WHERE project.title = ?
 LIMIT ? OFFSET ?]
[parameters: ('first_project', 1, 0)]
(Background on this error at: http://sqlalche.me/e/13/e3q8)
2020-07-25 12:30:34,176 INFO: Flask-Template-Site startup [in /home/jesse/PycharmProjects/Flask_template_site/app/__init__.py:60]
2020-07-25 12:30:43,267 INFO: Flask-Template-Site startup [in /home/jesse/PycharmProjects/Flask_template_site/app/__init__.py:60]
2020-07-25 12:30:47,692 INFO: Flask-Template-Site startup [in /home/jesse/PycharmProjects/Flask_template_site/app/__init__.py:60]
2020-07-25 12:30:55,496 INFO: Flask-Template-Site startup [in /home/jesse/PycharmProjects/Flask_template_site/app/__init__.py:60]
2020-07-25 12:30:59,452 INFO: Flask-Template-Site startup [in /home/jesse/PycharmProjects/Flask_template_site/app/__init__.py:60]
2020-07-25 12:32:52,450 INFO: Flask-Template-Site startup [in /home/jesse/PycharmProjects/Flask_template_site/app/__init__.py:60]
2020-07-25 12:36:22,105 INFO: Flask-Template-Site startup [in /home/jesse/PycharmProjects/Flask_template_site/app/__init__.py:60]
2020-07-25 12:36:53,268 ERROR: Exception on /new_project [POST] [in /home/jesse/PycharmProjects/Flask_template_site/venv/lib/python3.8/site-packages/flask/app.py:1891]
Traceback (most recent call last):
  File "/home/jesse/PycharmProjects/Flask_template_site/venv/lib/python3.8/site-packages/flask/app.py", line 2447, in wsgi_app
    response = self.full_dispatch_request()
  File "/home/jesse/PycharmProjects/Flask_template_site/venv/lib/python3.8/site-packages/flask/app.py", line 1952, in full_dispatch_request
    rv = self.handle_user_exception(e)
  File "/home/jesse/PycharmProjects/Flask_template_site/venv/lib/python3.8/site-packages/flask/app.py", line 1821, in handle_user_exception
    reraise(exc_type, exc_value, tb)
  File "/home/jesse/PycharmProjects/Flask_template_site/venv/lib/python3.8/site-packages/flask/_compat.py", line 39, in reraise
    raise value
  File "/home/jesse/PycharmProjects/Flask_template_site/venv/lib/python3.8/site-packages/flask/app.py", line 1950, in full_dispatch_request
    rv = self.dispatch_request()
  File "/home/jesse/PycharmProjects/Flask_template_site/venv/lib/python3.8/site-packages/flask/app.py", line 1936, in dispatch_request
    return self.view_functions[rule.endpoint](**req.view_args)
  File "/home/jesse/PycharmProjects/Flask_template_site/venv/lib/python3.8/site-packages/flask_login/utils.py", line 272, in decorated_view
    return func(*args, **kwargs)
  File "/home/jesse/PycharmProjects/Flask_template_site/app/routes.py", line 112, in new_project
    project = Project(title=form.project_title.data, description=form.description.data,
  File "<string>", line 4, in __init__
  File "/home/jesse/PycharmProjects/Flask_template_site/venv/lib/python3.8/site-packages/sqlalchemy/orm/state.py", line 433, in _initialize_instance
    manager.dispatch.init_failure(self, args, kwargs)
  File "/home/jesse/PycharmProjects/Flask_template_site/venv/lib/python3.8/site-packages/sqlalchemy/util/langhelpers.py", line 68, in __exit__
    compat.raise_(
  File "/home/jesse/PycharmProjects/Flask_template_site/venv/lib/python3.8/site-packages/sqlalchemy/util/compat.py", line 178, in raise_
    raise exception
  File "/home/jesse/PycharmProjects/Flask_template_site/venv/lib/python3.8/site-packages/sqlalchemy/orm/state.py", line 430, in _initialize_instance
    return manager.original_init(*mixed[1:], **kwargs)
  File "/home/jesse/PycharmProjects/Flask_template_site/venv/lib/python3.8/site-packages/sqlalchemy/ext/declarative/base.py", line 842, in _declarative_constructor
    setattr(self, k, kwargs[k])
  File "/home/jesse/PycharmProjects/Flask_template_site/venv/lib/python3.8/site-packages/sqlalchemy/orm/attributes.py", line 272, in __set__
    self.impl.set(
  File "/home/jesse/PycharmProjects/Flask_template_site/venv/lib/python3.8/site-packages/sqlalchemy/orm/attributes.py", line 1019, in set
    value = self.fire_replace_event(state, dict_, value, old, initiator)
  File "/home/jesse/PycharmProjects/Flask_template_site/venv/lib/python3.8/site-packages/sqlalchemy/orm/attributes.py", line 1041, in fire_replace_event
    value = fn(
  File "/home/jesse/PycharmProjects/Flask_template_site/venv/lib/python3.8/site-packages/sqlalchemy/orm/attributes.py", line 1451, in emit_backref_from_scalar_set_event
    instance_state(child),
AttributeError: 'int' object has no attribute '_sa_instance_state'
2020-07-25 12:37:20,973 INFO: Flask-Template-Site startup [in /home/jesse/PycharmProjects/Flask_template_site/app/__init__.py:60]
2020-07-25 12:37:25,125 INFO: Flask-Template-Site startup [in /home/jesse/PycharmProjects/Flask_template_site/app/__init__.py:60]
2020-07-25 12:37:29,647 INFO: Flask-Template-Site startup [in /home/jesse/PycharmProjects/Flask_template_site/app/__init__.py:60]
2020-07-25 12:37:33,582 INFO: Flask-Template-Site startup [in /home/jesse/PycharmProjects/Flask_template_site/app/__init__.py:60]
